
# Request for Resolution

## Summary
Ingestion pipeline failed for Advanced AI Research Reports_.html due to ValueError

## Error & Stack Trace
```python
Traceback (most recent call last):
  File "D:\Developer\LLM\proj_context_engineering\test_run_copilot\meta_context_system\meta_context_studio\src\ingestion\pipeline.py", line 112, in run_ingestion_pipeline
    interpreted_document = self.ingest_document(file_path, doc_type)
                           ^^^^^^^^^^^^^^^^^^^^^^^^^^^^^^^^^^^^^^^^^
  File "D:\Developer\LLM\proj_context_engineering\test_run_copilot\meta_context_system\meta_context_studio\src\ingestion\pipeline.py", line 80, in ingest_document
    self.vector_store.add_document(interpreted_document)
  File "D:\Developer\LLM\proj_context_engineering\test_run_copilot\meta_context_system\meta_context_studio\src\knowledge_base\vector_store.py", line 22, in add_document
    self.collection.add(
  File "D:\Developer\LLM\proj_context_engineering\test_run_copilot\meta_context_system\venv\Lib\site-packages\chromadb\api\models\Collection.py", line 80, in add
    add_request = self._validate_and_prepare_add_request(
                  ^^^^^^^^^^^^^^^^^^^^^^^^^^^^^^^^^^^^^^^
  File "D:\Developer\LLM\proj_context_engineering\test_run_copilot\meta_context_system\venv\Lib\site-packages\chromadb\api\models\CollectionCommon.py", line 95, in wrapper
    return func(self, *args, **kwargs)
           ^^^^^^^^^^^^^^^^^^^^^^^^^^^
  File "D:\Developer\LLM\proj_context_engineering\test_run_copilot\meta_context_system\venv\Lib\site-packages\chromadb\api\models\CollectionCommon.py", line 219, in _validate_and_prepare_add_request
    validate_insert_record_set(record_set=add_records)
  File "D:\Developer\LLM\proj_context_engineering\test_run_copilot\meta_context_system\venv\Lib\site-packages\chromadb\api\types.py", line 314, in validate_insert_record_set
    validate_metadatas(record_set["metadatas"])
  File "D:\Developer\LLM\proj_context_engineering\test_run_copilot\meta_context_system\venv\Lib\site-packages\chromadb\api\types.py", line 791, in validate_metadatas
    validate_metadata(metadata)
  File "D:\Developer\LLM\proj_context_engineering\test_run_copilot\meta_context_system\venv\Lib\site-packages\chromadb\api\types.py", line 757, in validate_metadata
    raise ValueError(
ValueError: Expected metadata value to be a str, int, float, bool, or None, got ['stl_', 'stl_02'] which is a AttributeValueList in add.

```

## Code Context
- File: D:\Developer\LLM\proj_context_engineering\test_run_copilot\meta_context_system\meta_context_studio\src\ingestion\pipeline.py
- Function/Method: run_ingestion_pipeline
```python
                            break
                    
                    if frame: # Ensure frame is not None
                        lineno = frame.f_lineno
                        lines, start_lineno = inspect.getsourcelines(frame.f_code)

```

## Reproduction Steps
- Command: python D:\Developer\LLM\proj_context_engineering\test_run_copilot\meta_context_system\meta_context_studio/scripts/run_ingestion.py
- Input File: D:\Developer\LLM\proj_context_engineering\test_run_copilot\meta_context_system\ingestion_queue\Advanced AI Research Reports_.html

## System Environment
- Python Version: 3.12.3 (tags/v3.12.3:f6650f9, Apr  9 2024, 14:05:25) [MSC v.1938 64 bit (AMD64)]
- Operating System: Windows 11
- Key Dependencies:
  - haystack-ai
  - chroma-haystack
  - sentence-transformers
  - markdown-it-py
  - beautifulsoup4
  - lxml
  - fastapi
  - uvicorn
  - langchain
  - pydantic
  - chromadb
  - rdflib

## Intended vs. Actual Behavior
The ingestion pipeline was intended to process Advanced AI Research Reports_.html but encountered an error.
